2021-03-19 23:11:28,146 INFO: Microblog startup [in /home/sebastian/workspaceu/test_fullStack/app/__init__.py:43]
2021-03-19 23:11:41,271 ERROR: Exception on /edit_profile [POST] [in /home/sebastian/workspaceu/test_fullStack/venv/lib/python3.8/site-packages/flask/app.py:1891]
Traceback (most recent call last):
  File "/home/sebastian/workspaceu/test_fullStack/venv/lib/python3.8/site-packages/sqlalchemy/engine/base.py", line 1705, in _execute_context
    self.dialect.do_execute(
  File "/home/sebastian/workspaceu/test_fullStack/venv/lib/python3.8/site-packages/sqlalchemy/engine/default.py", line 681, in do_execute
    cursor.execute(statement, parameters)
sqlite3.IntegrityError: UNIQUE constraint failed: user.username

The above exception was the direct cause of the following exception:

Traceback (most recent call last):
  File "/home/sebastian/workspaceu/test_fullStack/venv/lib/python3.8/site-packages/flask/app.py", line 2447, in wsgi_app
    response = self.full_dispatch_request()
  File "/home/sebastian/workspaceu/test_fullStack/venv/lib/python3.8/site-packages/flask/app.py", line 1952, in full_dispatch_request
    rv = self.handle_user_exception(e)
  File "/home/sebastian/workspaceu/test_fullStack/venv/lib/python3.8/site-packages/flask/app.py", line 1821, in handle_user_exception
    reraise(exc_type, exc_value, tb)
  File "/home/sebastian/workspaceu/test_fullStack/venv/lib/python3.8/site-packages/flask/_compat.py", line 39, in reraise
    raise value
  File "/home/sebastian/workspaceu/test_fullStack/venv/lib/python3.8/site-packages/flask/app.py", line 1950, in full_dispatch_request
    rv = self.dispatch_request()
  File "/home/sebastian/workspaceu/test_fullStack/venv/lib/python3.8/site-packages/flask/app.py", line 1936, in dispatch_request
    return self.view_functions[rule.endpoint](**req.view_args)
  File "/home/sebastian/workspaceu/test_fullStack/venv/lib/python3.8/site-packages/flask_login/utils.py", line 272, in decorated_view
    return func(*args, **kwargs)
  File "/home/sebastian/workspaceu/test_fullStack/app/routes.py", line 94, in edit_profile
    db.session.commit()
  File "<string>", line 2, in commit
  File "/home/sebastian/workspaceu/test_fullStack/venv/lib/python3.8/site-packages/sqlalchemy/orm/session.py", line 1406, in commit
    self._transaction.commit(_to_root=self.future)
  File "/home/sebastian/workspaceu/test_fullStack/venv/lib/python3.8/site-packages/sqlalchemy/orm/session.py", line 820, in commit
    self._prepare_impl()
  File "/home/sebastian/workspaceu/test_fullStack/venv/lib/python3.8/site-packages/sqlalchemy/orm/session.py", line 799, in _prepare_impl
    self.session.flush()
  File "/home/sebastian/workspaceu/test_fullStack/venv/lib/python3.8/site-packages/sqlalchemy/orm/session.py", line 3224, in flush
    self._flush(objects)
  File "/home/sebastian/workspaceu/test_fullStack/venv/lib/python3.8/site-packages/sqlalchemy/orm/session.py", line 3364, in _flush
    transaction.rollback(_capture_exception=True)
  File "/home/sebastian/workspaceu/test_fullStack/venv/lib/python3.8/site-packages/sqlalchemy/util/langhelpers.py", line 70, in __exit__
    compat.raise_(
  File "/home/sebastian/workspaceu/test_fullStack/venv/lib/python3.8/site-packages/sqlalchemy/util/compat.py", line 198, in raise_
    raise exception
  File "/home/sebastian/workspaceu/test_fullStack/venv/lib/python3.8/site-packages/sqlalchemy/orm/session.py", line 3324, in _flush
    flush_context.execute()
  File "/home/sebastian/workspaceu/test_fullStack/venv/lib/python3.8/site-packages/sqlalchemy/orm/unitofwork.py", line 453, in execute
    rec.execute(self)
  File "/home/sebastian/workspaceu/test_fullStack/venv/lib/python3.8/site-packages/sqlalchemy/orm/unitofwork.py", line 627, in execute
    util.preloaded.orm_persistence.save_obj(
  File "/home/sebastian/workspaceu/test_fullStack/venv/lib/python3.8/site-packages/sqlalchemy/orm/persistence.py", line 234, in save_obj
    _emit_update_statements(
  File "/home/sebastian/workspaceu/test_fullStack/venv/lib/python3.8/site-packages/sqlalchemy/orm/persistence.py", line 998, in _emit_update_statements
    c = connection._execute_20(
  File "/home/sebastian/workspaceu/test_fullStack/venv/lib/python3.8/site-packages/sqlalchemy/engine/base.py", line 1520, in _execute_20
    return meth(self, args_10style, kwargs_10style, execution_options)
  File "/home/sebastian/workspaceu/test_fullStack/venv/lib/python3.8/site-packages/sqlalchemy/sql/elements.py", line 313, in _execute_on_connection
    return connection._execute_clauseelement(
  File "/home/sebastian/workspaceu/test_fullStack/venv/lib/python3.8/site-packages/sqlalchemy/engine/base.py", line 1389, in _execute_clauseelement
    ret = self._execute_context(
  File "/home/sebastian/workspaceu/test_fullStack/venv/lib/python3.8/site-packages/sqlalchemy/engine/base.py", line 1748, in _execute_context
    self._handle_dbapi_exception(
  File "/home/sebastian/workspaceu/test_fullStack/venv/lib/python3.8/site-packages/sqlalchemy/engine/base.py", line 1929, in _handle_dbapi_exception
    util.raise_(
  File "/home/sebastian/workspaceu/test_fullStack/venv/lib/python3.8/site-packages/sqlalchemy/util/compat.py", line 198, in raise_
    raise exception
  File "/home/sebastian/workspaceu/test_fullStack/venv/lib/python3.8/site-packages/sqlalchemy/engine/base.py", line 1705, in _execute_context
    self.dialect.do_execute(
  File "/home/sebastian/workspaceu/test_fullStack/venv/lib/python3.8/site-packages/sqlalchemy/engine/default.py", line 681, in do_execute
    cursor.execute(statement, parameters)
sqlalchemy.exc.IntegrityError: (sqlite3.IntegrityError) UNIQUE constraint failed: user.username
[SQL: UPDATE user SET username=?, about_me=? WHERE user.id = ?]
[parameters: ('juan', 'Holaaaa', 6)]
(Background on this error at: http://sqlalche.me/e/14/gkpj)
